Workbook

Sheet Übersicht
A1: Quartalsübersicht 2025Q3 - Zusammenfassung aller Mitarbeiter
A3: --- Monatliche Summen ---
A4: Monat | B4: Gesamtstunden | C4: Bonusberechtigte Stunden | D4: Bonusberechtigte Stunden Sonderprojekt
A5: Juli 2025 | B5: =SUM('A. Kokott'!F31,'C. Trapp SV'!F24,'D. Brucker'!F16,'E. Bieler'!F42,'E. Iago Barros de Oliveira'!F8,'H. Bektas'!F23,'J. Dorchies'!F15,'J. Dorn'!F37,'M. Bandlofsky'!F18,'M. Bandlofsky CAD'!F9,'O. Haag BS-CAD'!F43,'P. Bergner'!F13,'R. Böttiger'!F23,'R. Wagen CAD'!F23,'S. Schüler'!F45,'T. Trautmann'!F20,'U. Sutter ADM'!F20) | C5: =SUM('A. Kokott'!F32,'C. Trapp SV'!F25,'D. Brucker'!F17,'E. Bieler'!F43,'E. Iago Barros de Oliveira'!F9,'H. Bektas'!F24,'J. Dorchies'!F16,'J. Dorn'!F38,'M. Bandlofsky'!F19,'M. Bandlofsky CAD'!F10,'O. Haag BS-CAD'!F44,'P. Bergner'!F14,'R. Böttiger'!F24,'R. Wagen CAD'!F24,'S. Schüler'!F46,'T. Trautmann'!F21,'U. Sutter ADM'!F21) | D5: =SUM('A. Kokott'!F33,'C. Trapp SV'!F26,'D. Brucker'!F18,'E. Bieler'!F44,'E. Iago Barros de Oliveira'!F10,'H. Bektas'!F25,'J. Dorchies'!F17,'J. Dorn'!F39,'M. Bandlofsky'!F20,'M. Bandlofsky CAD'!F11,'O. Haag BS-CAD'!F45,'P. Bergner'!F15,'R. Böttiger'!F25,'R. Wagen CAD'!F25,'S. Schüler'!F47,'T. Trautmann'!F22,'U. Sutter ADM'!F22)
A6: August 2025 | B6: =SUM('A. Kokott'!F77,'C. Trapp SV'!F48,'D. Brucker'!F25,'E. Bieler'!F53,'H. Bektas'!F39,'J. Dorchies'!F24,'J. Dorn'!F75,'M. Bandlofsky'!F37,'M. Warner'!F14,'O. Haag BS-CAD'!F84,'P. Bergner'!F34,'R. Böttiger'!F47,'R. Wagen CAD'!F49,'S. Roßkopf'!F10,'S. Schüler'!F85,'T. Trautmann'!F64,'U. Sutter ADM'!F43) | C6: =SUM('A. Kokott'!F78,'C. Trapp SV'!F49,'D. Brucker'!F26,'E. Bieler'!F54,'H. Bektas'!F40,'J. Dorchies'!F25,'J. Dorn'!F76,'M. Bandlofsky'!F38,'M. Warner'!F15,'O. Haag BS-CAD'!F85,'P. Bergner'!F35,'R. Böttiger'!F48,'R. Wagen CAD'!F50,'S. Roßkopf'!F11,'S. Schüler'!F86,'T. Trautmann'!F65,'U. Sutter ADM'!F44) | D6: =SUM('A. Kokott'!F79,'C. Trapp SV'!F50,'D. Brucker'!F27,'E. Bieler'!F55,'H. Bektas'!F41,'J. Dorchies'!F26,'J. Dorn'!F77,'M. Bandlofsky'!F39,'M. Warner'!F16,'O. Haag BS-CAD'!F86,'P. Bergner'!F36,'R. Böttiger'!F49,'R. Wagen CAD'!F51,'S. Roßkopf'!F12,'S. Schüler'!F87,'T. Trautmann'!F66,'U. Sutter ADM'!F45)
A7: September 2025 | B7: =SUM('A. Kokott'!F123,'C. Trapp SV'!F66,'D. Brucker'!F39,'E. Bieler'!F63,'H. Bektas'!F56,'J. Dorn'!F103,'M. Bandlofsky'!F64,'M. Bandlofsky CAD'!F19,'M. Warner'!F29,'O. Haag BS-CAD'!F127,'P. Bergner'!F55,'R. Böttiger'!F70,'R. Wagen CAD'!F63,'S. Roßkopf'!F22,'S. Schüler'!F118,'T. Trautmann'!F97,'U. Sutter ADM'!F60) | C7: =SUM('A. Kokott'!F124,'C. Trapp SV'!F67,'D. Brucker'!F40,'E. Bieler'!F64,'H. Bektas'!F57,'J. Dorn'!F104,'M. Bandlofsky'!F65,'M. Bandlofsky CAD'!F20,'M. Warner'!F30,'O. Haag BS-CAD'!F128,'P. Bergner'!F56,'R. Böttiger'!F71,'R. Wagen CAD'!F64,'S. Roßkopf'!F23,'S. Schüler'!F119,'T. Trautmann'!F98,'U. Sutter ADM'!F61) | D7: =SUM('A. Kokott'!F125,'C. Trapp SV'!F68,'D. Brucker'!F41,'E. Bieler'!F65,'H. Bektas'!F58,'J. Dorn'!F105,'M. Bandlofsky'!F66,'M. Bandlofsky CAD'!F21,'M. Warner'!F31,'O. Haag BS-CAD'!F129,'P. Bergner'!F57,'R. Böttiger'!F72,'R. Wagen CAD'!F65,'S. Roßkopf'!F24,'S. Schüler'!F120,'T. Trautmann'!F99,'U. Sutter ADM'!F62)
A9: --- Quartalssummen ---
A10: Gesamt eingetragene Stunden: | B10: =SUM('A. Kokott'!B136,'C. Trapp SV'!B82,'D. Brucker'!B52,'E. Bieler'!B76,'E. Iago Barros de Oliveira'!B19,'H. Bektas'!B69,'J. Dorchies'!B36,'J. Dorn'!B116,'M. Bandlofsky'!B80,'M. Bandlofsky CAD'!B31,'M. Warner'!B41,'O. Haag BS-CAD'!B140,'P. Bergner'!B71,'R. Böttiger'!B83,'R. Wagen CAD'!B76,'S. Roßkopf'!B34,'S. Schüler'!B131,'T. Trautmann'!B110,'U. Sutter ADM'!B73)
A11: Bonusberechtigte Stunden (Quartal): | B11: =SUM('A. Kokott'!B138,'C. Trapp SV'!B84,'D. Brucker'!B54,'E. Bieler'!B78,'E. Iago Barros de Oliveira'!B21,'H. Bektas'!B71,'J. Dorchies'!B38,'J. Dorn'!B118,'M. Bandlofsky'!B82,'M. Bandlofsky CAD'!B33,'M. Warner'!B43,'O. Haag BS-CAD'!B142,'P. Bergner'!B73,'R. Böttiger'!B85,'R. Wagen CAD'!B78,'S. Roßkopf'!B36,'S. Schüler'!B133,'T. Trautmann'!B112,'U. Sutter ADM'!B75)
A12: Bonusberechtigte Stunden Sonderprojekt (Quartal): | B12: =SUM('A. Kokott'!B139,'C. Trapp SV'!B85,'D. Brucker'!B55,'E. Bieler'!B79,'E. Iago Barros de Oliveira'!B22,'H. Bektas'!B72,'J. Dorchies'!B39,'J. Dorn'!B119,'M. Bandlofsky'!B83,'M. Bandlofsky CAD'!B34,'M. Warner'!B44,'O. Haag BS-CAD'!B143,'P. Bergner'!B74,'R. Böttiger'!B86,'R. Wagen CAD'!B79,'S. Roßkopf'!B37,'S. Schüler'!B134,'T. Trautmann'!B113,'U. Sutter ADM'!B76)
A14: --- Mitarbeiter in diesem Quartal ---
A15: A. Kokott
A16: C. Trapp SV
A17: D. Brucker
A18: E. Bieler
A19: E. Iago Barros de Oliveira
A20: H. Bektas
A21: J. Dorchies
A22: J. Dorn
A23: M. Bandlofsky
A24: M. Bandlofsky CAD
A25: M. Warner
... A33: U. Sutter ADM

Sheet Projekt-Budget-Übersicht
A1: Projekt-Budget-Übersicht
A3: Hinweis: Rote Zellen = Manuelle Eingabe erforderlich | Gelbe Zellen = Optional manuell anpassen
A5: Projekt | B5: Obermeilenstein | C5: Abrechnungsart | D5: Status | E5: Gesamtbudget (€) | F5: Abgerechnet (€) | G5: Verfügbar (€) | H5: Stundensatz SV (€/h) | I5: Stundensatz CAD (€/h) | J5: Stundensatz ADM (€/h) | K5: Bemerkung
A6: 0.1000 PM Allgemeinprojekt | B6: ● PM Projektvorbereitung/Dokumentation | C6: Unbekannt | D6: ⚠ Manual erforderlich | F6: 0 | G6: =E6-F6 | K6: Abrechnungsart wählen; Stundensätze eingeben
A7: 0.1000 PM Allgemeinprojekt | B7: ● PM Einarbeitung neuer Mitarbeiter | C7: Unbekannt | D7: ⚠ Manual erforderlich | F7: 0 | G7: =E7-F7 | K7: Abrechnungsart wählen; Stundensätze eingeben
A8: 0.1000 PM Allgemeinprojekt | B8: ● PM Teilnahme Meetings | C8: Unbekannt | D8: ⚠ Manual erforderlich | F8: 0 | G8: =E8-F8 | K8: Abrechnungsart wählen; Stundensätze eingeben
A9: 0.1000 PM Allgemeinprojekt | B9: ● PM Onboarding | C9: Unbekannt | D9: ⚠ Manual erforderlich | F9: 0 | G9: =E9-F9 | K9: Abrechnungsart wählen; Stundensätze eingeben
A10: 0.1000 PM Allgemeinprojekt | B10: ● PM Vertragswesen | C10: Unbekannt | D10: ⚠ Manual erforderlich | F10: 0 | G10: =E10-F10 | K10: Abrechnungsart wählen; Stundensätze eingeben
A11: 0.1000 PM Allgemeinprojekt | B11: ● PM Portalanlage und Pflege | C11: Unbekannt | D11: ⚠ Manual erforderlich | F11: 0 | G11: =E11-F11 | K11: Abrechnungsart wählen; Stundensätze eingeben
A12: 0.1000 PM Allgemeinprojekt | B12: ● SAP Schulungen | C12: Unbekannt | D12: ⚠ Manual erforderlich | F12: 0 | G12: =E12-F12 | K12: Abrechnungsart wählen; Stundensätze eingeben
A13: 0.1000 PM Allgemeinprojekt | B13: ● SAP Projekt | C13: Unbekannt | D13: ⚠ Manual erforderlich | F13: 0 | G13: =E13-F13 | K13: Abrechnungsart wählen; Stundensätze eingeben
A14: 0.1000 PM Allgemeinprojekt | B14: ● uStrich Umstellung uStrich/X4 | C14: Unbekannt | D14: ⚠ Manual erforderlich | F14: 0 | G14: =E14-F14 | K14: Abrechnungsart wählen; Stundensätze eingeben
A15: 0000 Sonderprojekt für Bonus | B15: ● Erfassung für | C15: Unbekannt | D15: ⚠ Manual erforderlich | F15: 0 | G15: =E15-F15 | K15: Abrechnungsart wählen; Stundensätze eingeben
A16: 0283.05 D+R-BAB-Lokalbhf-Dreieichstr59-FFM | B16: ● (p) Pos. 1 Feuerwehrpläne | C16: Pauschale | D16: ⚠ Manual erforderlich | F16: 0 | G16: =E16-F16 | H16: 0 | I16: 0 | J16: 0 | K16: Stundensätze eingeben
A17: 0283.05 D+R-BAB-Lokalbhf-Dreieichstr59-FFM | B17: ● (aN) BAB | C17: Nachweis | D17: ⚠ Manual erforderlich | F17: 0 | G17: =E17-F17 | K17: Stundensätze eingeben
A18: 0299.02 BSK-Franziska Schervier-Lange-Straße-10-16-Ffm-Altenpflegeheim | B18: ● (p) Pos.1 Fortschr. bestehendes BSK | C18: Pauschale | D18: ⚠ Manual erforderlich | F18: 0 | G18: =E18-F18 | H18: 0 | I18: 0 | J18: 0 | K18: Stundensätze eingeben
A19: 0299.02 BSK-Franziska Schervier-Lange-Straße-10-16-Ffm-Altenpflegeheim | B19: ● (a.N.) Pos.2 BAB + Qualitätsüberwachung | C19: Nachweis | D19: ⚠ Manual erforderlich | F19: 0 | G19: =E19-F19 | K19: Stundensätze eingeben
A20: 0569.03 RUR-BSK-Gutleutstr85-Frankfurt-Hotel-Roomers | B20: ● • (p) Pos. 1 Erstellung BSK | C20: Pauschale | D20: ⚠ Manual erforderlich | F20: 0 | G20: =E20-F20 | H20: 0 | I20: 0 | J20: 0 | K20: Stundensätze eingeben
A21: 0569.03 RUR-BSK-Gutleutstr85-Frankfurt-Hotel-Roomers | B21: ● • (p) Pos. 2 Auftragsbearbeitung (ADM) | C21: Pauschale | D21: ⚠ Manual erforderlich | F21: 0 | G21: =E21-F21 | H21: 0 | I21: 0 | J21: 0 | K21: Stundensätze eingeben
A22: 0683.07 BSK-Hanauer-Landstraße-147-149-Ffm | B22: ● (a.N.) BTB zur Nutzungsänderung 2. OG | C22: Nachweis | D22: ⚠ Manual erforderlich | F22: 0 | G22: =E22-F22 | K22: Stundensätze eingeben
A23: 0683.07 BSK-Hanauer-Landstraße-147-149-Ffm | B23: ● (p) Fortschr. BSK Teilumnutzung Souterrain als Kantine | C23: Pauschale | D23: ⚠ Manual erforderlich | F23: 0 | G23: =E23-F23 | H23: 0 | I23: 0 | J23: 0 | K23: Stundensätze eingeben
A24: 0683.07 BSK-Hanauer-Landstraße-147-149-Ffm | B24: ● (a.N.) Abstimmung Genehmigungsbehörden | C24: Nachweis | D24: ⚠ Manual erforderlich | F24: 0 | G24: =E24-F24 | K24: Stundensätze eingeben
A25: 0683.07 BSK-Hanauer-Landstraße-147-149-Ffm | B25: ● (a.N.) BAB | C25: Nachweis | D25: ⚠ Manual erforderlich | F25: 0 | G25: =E25-F25 | K25: Stundensätze eingeben
A26: 0710.01 Zeilpavillon-Zeil-104-Frankfurt-Weidenhof | B26: ● 2000-Vorplanung | C26: Unbekannt | D26: ⚠ Manual erforderlich | F26: 0 | G26: =E26-F26 | K26: Abrechnungsart wählen; Stundensätze eingeben
A27: 0757.17 Patrizia GrundInvest Objekt Hofheim GmbH & Co. KG | B27: ● (aN) Pos.1 KOF Umnutzung Fitnessstudio | C27: Nachweis | D27: ⚠ Manual erforderlich | F27: 0 | G27: =E27-F27 | K27: Stundensätze eingeben
A28: 0757.19 GermanReal-BST-Chinon-Platz-Hofheim-Chinon-Center-Eiswagen | B28: ● (aN) Pos.1 BST bezüglich des Eiswagens am Chinon Center | C28: Nachweis | D28: ⚠ Manual erforderlich | F28: 0 | G28: =E28-F28 | K28: Stundensätze eingeben
A29: 0815.07 Beratung-MPI-Hirnforschung-Ffm | B29: ● 3000-Entwurfsplanung | C29: Unbekannt | D29: ⚠ Manual erforderlich | F29: 0 | G29: =E29-F29 | K29: Abrechnungsart wählen; Stundensätze eingeben
A30: 0815.09 MPI-BTB-Z-HIRN-Umbau-Max-von-Laue-Str4-FFM | B30: ● (aN) Pos. 1 Brandschutztechnische Beratung in der Planungsphase | C30: Nachweis | D30: ⚠ Manual erforderlich | F30: 0 | G30: =E30-F30 | K30: Stundensätze eingeben
A31: 0815.10 MPI-Fortschr-BSK-Z-HIRN-Umbau-Tierhaus-Max-von-Laue-Str4-FFM | B31: ● (p) Pos. 1 Fortschr | C31: Pauschale | D31: ⚠ Manual erforderlich | F31: 0 | G31: =E31-F31 | H31: 0 | I31: 0 | J31: 0 | K31: Stundensätze eingeben
A32: 1015.02 VuBBaWü-BTB-Kurfürstenanlage15-HD-Justizzentrum | B32: ● (aN) 3.1.1.1 Überprüfung des Brandschutzkonzepts und brandschutztechnische Beratung | C32: Nachweis | D32: ⚠ Manual erforderlich | F32: 0 | G32: =E32-F32 | K32: Stundensätze eingeben
A33: 1015.02 VuBBaWü-BTB-Kurfürstenanlage15-HD-Justizzentrum | B33: ● (aN) 3.1.1.2 Begleitung bei der Durchführung der Maßnahmen | C33: Nachweis | D33: ⚠ Manual erforderlich | F33: 0 | G33: =E33-F33 | K33: Stundensätze eingeben
A34: 1015.02 VuBBaWü-BTB-Kurfürstenanlage15-HD-Justizzentrum | B34: ● (p) 3.1.1.3 Fortschreibung des Brandschutzkonzepts bzgl. der Überarbeitung des Sicherheitskonzepts | C34: Pauschale | D34: ⚠ Manual erforderlich | F34: 0 | G34: =E34-F34 | H34: 0 | I34: 0 | J34: 0 | K34: Stundensätze eingeben
A35: 1015.02 VuBBaWü-BTB-Kurfürstenanlage15-HD-Justizzentrum | B35: ● ADM | C35: Unbekannt | D35: ⚠ Manual erforderlich | F35: 0 | G35: =E35-F35 | K35: Abrechnungsart wählen; Stundensätze eingeben
A36: 1123.04 Fortschr.-BSK-U-Bahnstation-Dom-Römer-Frankfurt | B36: ● (p) Pos.1 Fortschr. BSK für Stadtbahnstation Dom/Römer | C36: Pauschale | D36: ⚠ Manual erforderlich | F36: 0 | G36: =E36-F36 | H36: 0 | I36: 0 | J36: 0 | K36: Stundensätze eingeben
A37: 1159.01 Lilienthalstraße-7-Regensburg-EON | B37: ● Beurteilung erhöhter Personenbelegung (pauschal) | C37: Unbekannt | D37: ⚠ Manual erforderlich | F37: 0 | G37: =E37-F37 | K37: Abrechnungsart wählen; Stundensätze eingeben
A38: 1159.01 Lilienthalstraße-7-Regensburg-EON | B38: ● Fortschr. BSK Personenbelegung (pauschal) | C38: Unbekannt | D38: ⚠ Manual erforderlich | F38: 0 | G38: =E38-F38 | K38: Abrechnungsart wählen; Stundensätze eingeben
A39: 1208.04 NT01-BTB-Gymnasium-Riedberg-Friedrich-Dessauer-Str-2-Ffm-Batteriespeicher | B39: ● (aN) Pos.1 BTB zur Abnahme und Bewertung des Batteriespeichers | C39: Nachweis | D39: ⚠ Manual erforderlich | F39: 0 | G39: =E39-F39 | K39: Stundensätze eingeben
A40: 1257.03 LP3-8-Germersheim-Army-Depot-Gebäude-7915 | B40: ● 3000-Entwurfsplanung | C40: Unbekannt | D40: ⚠ Manual erforderlich | F40: 0 | G40: =E40-F40 | K40: Abrechnungsart wählen; Stundensätze eingeben
A41: 1257.03 LP3-8-Germersheim-Army-Depot-Gebäude-7915 | B41: ● 5000-Ausführungsplanung | C41: Unbekannt | D41: ⚠ Manual erforderlich | F41: 0 | G41: =E41-F41 | K41: Abrechnungsart wählen; Stundensätze eingeben
A42: 1257.03 LP3-8-Germersheim-Army-Depot-Gebäude-7915 | B42: ● 8000-Objektüberwachung | C42: Unbekannt | D42: ⚠ Manual erforderlich | F42: 0 | G42: =E42-F42 | K42: Abrechnungsart wählen; Stundensätze eingeben
...

Sheet A. Kokott
A1: A. Kokott - Quartalsreport 2025Q3
A2: Position: | B2: SV
A4: --- Juli 2025 ---
A5: Projekt | B5: Meilenstein | C5: Typ | D5: Soll (h) | E5: Ist (h) | F5: Juli 2025 (h) | G5: % | H5: Bonus-Anpassung (h) | I5: Differenz (h) | J5: Zuordnen an | K5: Von anderen (h) | L5: Stundensatz (€/h) | M5: Umsatz (€) | N5: Budget Gesamt (€) | O5: Budget Ist (€) | P5: Budget Erwirtschaftet (€)
A6: 0000 Sonderprojekt für Bonus | B6: Angebote-Ausschreibungen-Kalkulationen (max. 8h/Monat pro MA) | C6: M | D6: 8 | E6: 8 | F6: 8 | G6: 100 | I6: =IF(H6=0,"",F6-H6) | K6: =IF('D. Brucker'!J6="A. Kokott",'D. Brucker'!I6,0)+IF('E. Bieler'!J6="A. Kokott",'E. Bieler'!I6,0)+IF('J. Dorchies'!J6="A. Kokott",'J. Dorchies'!I6,0)+IF('O. Haag BS-CAD'!J6="A. Kokott",'O. Haag BS-CAD'!I6,0)+IF('S. Schüler'!J6="A. Kokott",'S. Schüler'!I6,0)+IF('T. Trautmann'!J6="A. Kokott",'T. Trautmann'!I6,0)+IF('U. Sutter ADM'!J6="A. Kokott",'U. Sutter ADM'!I6,0) | L6: =IF($B$2="-","",IF($B$2="Pauschale",IFERROR(INDEX('Projekt-Budget-Übersicht'!$H:$H,MATCH(A6,'Projekt-Budget-Übersicht'!$A:$A,0)),""),IF($B$2="SV",IFERROR(INDEX('Projekt-Budget-Übersicht'!$H:$H,MATCH(A6,'Projekt-Budget-Übersicht'!$A:$A,0)),""),IF($B$2="CAD",IFERROR(INDEX('Projekt-Budget-Übersicht'!$I:$I,MATCH(A6,'Projekt-Budget-Übersicht'!$A:$A,0)),""),IF($B$2="ADM",IFERROR(INDEX('Projekt-Budget-Übersicht'!$J:$J,MATCH(A6,'Projekt-Budget-Übersicht'!$A:$A,0)),""),""))))) | M6: =IF($B$2="-","",L6*(F6+I6+K6)) | N6: =IFERROR(INDEX('Projekt-Budget-Übersicht'!$E:$E,MATCH(A6,'Projekt-Budget-Übersicht'!$A:$A,0)),"")
B7: Einarbeitung neuer Mitarbeiter (max. 8h/Monat pro MA) | C7: M | D7: 8 | E7: 8 | F7: 8 | G7: 100 | I7: =IF(H7=0,"",F7-H7) | K7: =IF('C. Trapp SV'!J6="A. Kokott",'C. Trapp SV'!I6,0)+IF('D. Brucker'!J7="A. Kokott",'D. Brucker'!I7,0)+IF('E. Bieler'!J7="A. Kokott",'E. Bieler'!I7,0)+IF('J. Dorchies'!J7="A. Kokott",'J. Dorchies'!I7,0)+IF('J. Dorn'!J6="A. Kokott",'J. Dorn'!I6,0)+IF('M. Bandlofsky'!J6="A. Kokott",'M. Bandlofsky'!I6,0)+IF('T. Trautmann'!J7="A. Kokott",'T. Trautmann'!I7,0)+IF('U. Sutter ADM'!J7="A. Kokott",'U. Sutter ADM'!I7,0) | L7: =IF($B$2="-","",IF($B$2="Pauschale",IFERROR(INDEX('Projekt-Budget-Übersicht'!$H:$H,MATCH(A7,'Projekt-Budget-Übersicht'!$A:$A,0)),""),IF($B$2="SV",IFERROR(INDEX('Projekt-Budget-Übersicht'!$H:$H,MATCH(A7,'Projekt-Budget-Übersicht'!$A:$A,0)),""),IF($B$2="CAD",IFERROR(INDEX('Projekt-Budget-Übersicht'!$I:$I,MATCH(A7,'Projekt-Budget-Übersicht'!$A:$A,0)),""),IF($B$2="ADM",IFERROR(INDEX('Projekt-Budget-Übersicht'!$J:$J,MATCH(A7,'Projekt-Budget-Übersicht'!$A:$A,0)),""),""))))) | M7: =IF($B$2="-","",L7*(F7+I7+K7)) | N7: =IFERROR(INDEX('Projekt-Budget-Übersicht'!$E:$E,MATCH(A7,'Projekt-Budget-Übersicht'!$A:$A,0)),"")
A8: 0014 Urlaubstage | B8: 0001-Stunden ohne Leistungsphase | C8: G | D8: 0 | E8: 0 | F8: 50 | G8: 0 | I8: =IF(H8=0,"",F8-H8) | K8: 0 | L8: =IF($B$2="-","",IF($B$2="Pauschale",IFERROR(INDEX('Projekt-Budget-Übersicht'!$H:$H,MATCH(A8,'Projekt-Budget-Übersicht'!$A:$A,0)),""),IF($B$2="SV",IFERROR(INDEX('Projekt-Budget-Übersicht'!$H:$H,MATCH(A8,'Projekt-Budget-Übersicht'!$A:$A,0)),""),IF($B$2="CAD",IFERROR(INDEX('Projekt-Budget-Übersicht'!$I:$I,MATCH(A8,'Projekt-Budget-Übersicht'!$A:$A,0)),""),IF($B$2="ADM",IFERROR(INDEX('Projekt-Budget-Übersicht'!$J:$J,MATCH(A8,'Projekt-Budget-Übersicht'!$A:$A,0)),""),""))))) | M8: =IF($B$2="-","",L8*(F8+I8+K8)) | N8: =IFERROR(INDEX('Projekt-Budget-Übersicht'!$E:$E,MATCH(A8,'Projekt-Budget-Übersicht'!$A:$A,0)),"")
A9: 3869.24 KES-BST-1.OG-Bestandsgebäude-Marktstr1-3-Stuttgart | B9: ADM | C9: G | D9: 1 | E9: 1.25 | F9: 0.5 | G9: 125 | I9: =IF(H9=0,"",F9-H9) | K9: 0 | L9: =IF($B$2="-","",IF($B$2="Pauschale",IFERROR(INDEX('Projekt-Budget-Übersicht'!$H:$H,MATCH(A9,'Projekt-Budget-Übersicht'!$A:$A,0)),""),IF($B$2="SV",IFERROR(INDEX('Projekt-Budget-Übersicht'!$H:$H,MATCH(A9,'Projekt-Budget-Übersicht'!$A:$A,0)),""),IF($B$2="CAD",IFERROR(INDEX('Projekt-Budget-Übersicht'!$I:$I,MATCH(A9,'Projekt-Budget-Übersicht'!$A:$A,0)),""),IF($B$2="ADM",IFERROR(INDEX('Projekt-Budget-Übersicht'!$J:$J,MATCH(A9,'Projekt-Budget-Übersicht'!$A:$A,0)),""),""))))) | M9: =IF($B$2="-","",L9*(F9+I9+K9)) | N9: =IFERROR(INDEX('Projekt-Budget-Übersicht'!$E:$E,MATCH(A9,'Projekt-Budget-Übersicht'!$A:$A,0)),"")
A10: 5607.05 BAB-NB-J4-Zentralinstitut-für-seelische-Gesundheit-Mannheim | B10: 3100-Erarbeiten des Brandschutzkonzept/Nachweis/Stellungnahme | C10: G | D10: 29.75 | E10: 79.75 | F10: 0.5 | G10: 268.07 | I10: =IF(H10=0,"",F10-H10) | K10: 0 | L10: =IF($B$2="-","",IF($B$2="Pauschale",IFERROR(INDEX('Projekt-Budget-Übersicht'!$H:$H,MATCH(A10,'Projekt-Budget-Übersicht'!$A:$A,0)),""),IF($B$2="SV",IFERROR(INDEX('Projekt-Budget-Übersicht'!$H:$H,MATCH(A10,'Projekt-Budget-Übersicht'!$A:$A,0)),""),IF($B$2="CAD",IFERROR(INDEX('Projekt-Budget-Übersicht'!$I:$I,MATCH(A10,'Projekt-Budget-Übersicht'!$A:$A,0)),""),IF($B$2="ADM",IFERROR(INDEX('Projekt-Budget-Übersicht'!$J:$J,MATCH(A10,'Projekt-Budget-Übersicht'!$A:$A,0)),""),""))))) | M10: =IF($B$2="-","",L10*(F10+I10+K10)) | N10: =IFERROR(INDEX('Projekt-Budget-Übersicht'!$E:$E,MATCH(A10,'Projekt-Budget-Übersicht'!$A:$A,0)),"")
A11: 5640.12 Swisslife-BTB-BSK-HCIII-Salutem-4.OG-Eppelheimerstr8-Heidelberg | B11: CAD | C11: G | D11: 6 | E11: 2.75 | F11: 0.5 | G11: 45.83 | I11: =IF(H11=0,"",F11-H11) | K11: 0 | L11: =IF($B$2="-","",IF($B$2="Pauschale",IFERROR(INDEX('Projekt-Budget-Übersicht'!$H:$H,MATCH(A11,'Projekt-Budget-Übersicht'!$A:$A,0)),""),IF($B$2="SV",IFERROR(INDEX('Projekt-Budget-Übersicht'!$H:$H,MATCH(A11,'Projekt-Budget-Übersicht'!$A:$A,0)),""),IF($B$2="CAD",IFERROR(INDEX('Projekt-Budget-Übersicht'!$I:$I,MATCH(A11,'Projekt-Budget-Übersicht'!$A:$A,0)),""),IF($B$2="ADM",IFERROR(INDEX('Projekt-Budget-Übersicht'!$J:$J,MATCH(A11,'Projekt-Budget-Übersicht'!$A:$A,0)),""),""))))) | M11: =IF($B$2="-","",L11*(F11+I11+K11)) | N11: =IFERROR(INDEX('Projekt-Budget-Übersicht'!$E:$E,MATCH(A11,'Projekt-Budget-Übersicht'!$A:$A,0)),"")
A12: 5793.03 StadtFB-Eschholzstr118-Freiburg-Rettungszentrum-Halle-E | B12: (aN) Pos. 1 Brandschutztechnische Beratung | C12: G | D12: 20 | E12: 1.75 | F12: 0.5 | G12: 8.75 | I12: =IF(H12=0,"",F12-H12) | K12: 0 | L12: =IF($B$2="-","",IF($B$2="Pauschale",IFERROR(INDEX('Projekt-Budget-Übersicht'!$H:$H,MATCH(A12,'Projekt-Budget-Übersicht'!$A:$A,0)),""),IF($B$2="SV",IFERROR(INDEX('Projekt-Budget-Übersicht'!$H:$H,MATCH(A12,'Projekt-Budget-Übersicht'!$A:$A,0)),""),IF($B$2="CAD",IFERROR(INDEX('Projekt-Budget-Übersicht'!$I:$I,MATCH(A12,'Projekt-Budget-Übersicht'!$A:$A,0)),""),IF($B$2="ADM",IFERROR(INDEX('Projekt-Budget-Übersicht'!$J:$J,MATCH(A12,'Projekt-Budget-Übersicht'!$A:$A,0)),""),""))))) | M12: =IF($B$2="-","",L12*(F12+I12+K12)) | N12: =IFERROR(INDEX('Projekt-Budget-Übersicht'!$E:$E,MATCH(A12,'Projekt-Budget-Übersicht'!$A:$A,0)),"")
A13: 5984.01 QE-WEA-Windpark-Lusshardt-Überarbeitung-BSK | B13: ADM | C13: G | D13: 1 | E13: 1.25 | F13: 0.5 | G13: 125 | I13: =IF(H13=0,"",F13-H13) | K13: 0 | L13: =IF($B$2="-","",IF($B$2="Pauschale",IFERROR(INDEX('Projekt-Budget-Übersicht'!$H:$H,MATCH(A13,'Projekt-Budget-Übersicht'!$A:$A,0)),""),IF($B$2="SV",IFERROR(INDEX('Projekt-Budget-Übersicht'!$H:$H,MATCH(A13,'Projekt-Budget-Übersicht'!$A:$A,0)),""),IF($B$2="CAD",IFERROR(INDEX('Projekt-Budget-Übersicht'!$I:$I,MATCH(A13,'Projekt-Budget-Übersicht'!$A:$A,0)),""),IF($B$2="ADM",IFERROR(INDEX('Projekt-Budget-Übersicht'!$J:$J,MATCH(A13,'Projekt-Budget-Übersicht'!$A:$A,0)),""),""))))) | M13: =IF($B$2="-","",L13*(F13+I13+K13)) | N13: =IFERROR(INDEX('Projekt-Budget-Übersicht'!$E:$E,MATCH(A13,'Projekt-Budget-Übersicht'!$A:$A,0)),"")
A14: 6527.01 IO-Anp-BSK-Mühlenfeldstr1-Holzminden-Symotion | B14: SV | C14: G | D14: 6 | E14: 33.75 | F14: 0.25 | G14: 562.5 | I14: =IF(H14=0,"",F14-H14) | K14: =IF('E. Bieler'!J20="A. Kokott",'E. Bieler'!I20,0)+IF('J. Dorchies'!J9="A. Kokott",'J. Dorchies'!I9,0)+IF('J. Dorn'!J23="A. Kokott",'J. Dorn'!I23,0)+IF('P. Bergner'!J7="A. Kokott",'P. Bergner'!I7,0)+IF('R. Böttiger'!J13="A. Kokott",'R. Böttiger'!I13,0) | L14: =IF($B$2="-","",IF($B$2="Pauschale",IFERROR(INDEX('Projekt-Budget-Übersicht'!$H:$H,MATCH(A14,'Projekt-Budget-Übersicht'!$A:$A,0)),""),IF($B$2="SV",IFERROR(INDEX('Projekt-Budget-Übersicht'!$H:$H,MATCH(A14,'Projekt-Budget-Übersicht'!$A:$A,0)),""),IF($B$2="CAD",IFERROR(INDEX('Projekt-Budget-Übersicht'!$I:$I,MATCH(A14,'Projekt-Budget-Übersicht'!$A:$A,0)),""),IF($B$2="ADM",IFERROR(INDEX('Projekt-Budget-Übersicht'!$J:$J,MATCH(A14,'Projekt-Budget-Übersicht'!$A:$A,0)),""),""))))) | M14: =IF($B$2="-","",L14*(F14+I14+K14)) | N14: =IFERROR(INDEX('Projekt-Budget-Übersicht'!$E:$E,MATCH(A14,'Projekt-Budget-Übersicht'!$A:$A,0)),"")
A15: 6769.01 Juwi-Anp-BSK-Selser-Berg | B15: (p) Anp. BSK | C15: G | D15: 2 | E15: 3.5 | F15: 0.5 | G15: 175 | I15: =IF(H15=0,"",F15-H15) | K15: =IF('H. Bektas'!J6="A. Kokott",'H. Bektas'!I6,0) | L15: =IF($B$2="-","",IF($B$2="Pauschale",IFERROR(INDEX('Projekt-Budget-Übersicht'!$H:$H,MATCH(A15,'Projekt-Budget-Übersicht'!$A:$A,0)),""),IF($B$2="SV",IFERROR(INDEX('Projekt-Budget-Übersicht'!$H:$H,MATCH(A15,'Projekt-Budget-Übersicht'!$A:$A,0)),""),IF($B$2="CAD",IFERROR(INDEX('Projekt-Budget-Übersicht'!$I:$I,MATCH(A15,'Projekt-Budget-Übersicht'!$A:$A,0)),""),IF($B$2="ADM",IFERROR(INDEX('Projekt-Budget-Übersicht'!$J:$J,MATCH(A15,'Projekt-Budget-Übersicht'!$A:$A,0)),""),""))))) | M15: =IF($B$2="-","",L15*(F15+I15+K15)) | N15: =IFERROR(INDEX('Projekt-Budget-Übersicht'!$E:$E,MATCH(A15,'Projekt-Budget-Übersicht'!$A:$A,0)),"")
A16: 6961.01 Neptune-Rheinhafen-Speyer-allgemeineBeratungsleistungen | B16: (aN) BTB (SV) | C16: G | D16: 68 | E16: 47.25 | F16: 0.5 | G16: 69.49 | I16: =IF(H16=0,"",F16-H16) | K16: =IF('H. Bektas'!J7="A. Kokott",'H. Bektas'!I7,0) | L16: =IF($B$2="-","",IF($B$2="Pauschale",IFERROR(INDEX('Projekt-Budget-Übersicht'!$H:$H,MATCH(A16,'Projekt-Budget-Übersicht'!$A:$A,0)),""),IF($B$2="SV",IFERROR(INDEX('Projekt-Budget-Übersicht'!$H:$H,MATCH(A16,'Projekt-Budget-Übersicht'!$A:$A,0)),""),IF($B$2="CAD",IFERROR(INDEX('Projekt-Budget-Übersicht'!$I:$I,MATCH(A16,'Projekt-Budget-Übersicht'!$A:$A,0)),""),IF($B$2="ADM",IFERROR(INDEX('Projekt-Budget-Übersicht'!$J:$J,MATCH(A16,'Projekt-Budget-Übersicht'!$A:$A,0)),""),""))))) | M16: =IF($B$2="-","",L16*(F16+I16+K16)) | N16: =IFERROR(INDEX('Projekt-Budget-Übersicht'!$E:$E,MATCH(A16,'Projekt-Budget-Übersicht'!$A:$A,0)),"")
A17: 7015.02 HeyLagerGmbH-BAB-Garagenpark-Alzenau | B17: ADM | C17: G | D17: 1 | E17: 1.25 | F17: 0.5 | G17: 125 | I17: =IF(H17=0,"",F17-H17) | K17: 0 | L17: =IF($B$2="-","",IF($B$2="Pauschale",IFERROR(INDEX('Projekt-Budget-Übersicht'!$H:$H,MATCH(A17,'Projekt-Budget-Übersicht'!$A:$A,0)),""),IF($B$2="SV",IFERROR(INDEX('Projekt-Budget-Übersicht'!$H:$H,MATCH(A17,'Projekt-Budget-Übersicht'!$A:$A,0)),""),IF($B$2="CAD",IFERROR(INDEX('Projekt-Budget-Übersicht'!$I:$I,MATCH(A17,'Projekt-Budget-Übersicht'!$A:$A,0)),""),IF($B$2="ADM",IFERROR(INDEX('Projekt-Budget-Übersicht'!$J:$J,MATCH(A17,'Projekt-Budget-Übersicht'!$A:$A,0)),""),""))))) | M17: =IF($B$2="-","",L17*(F17+I17+K17)) | N17: =IFERROR(INDEX('Projekt-Budget-Übersicht'!$E:$E,MATCH(A17,'Projekt-Budget-Übersicht'!$A:$A,0)),"")
A18: 7090.01 Baupionier-BSK-Garagenpark-Eckersmühlen | B18: ADM | C18: G | D18: 1 | E18: 1.75 | F18: 0.25 | G18: 175 | I18: =IF(H18=0,"",F18-H18) | K18: 0 | L18: =IF($B$2="-","",IF($B$2="Pauschale",IFERROR(INDEX('Projekt-Budget-Übersicht'!$H:$H,MATCH(A18,'Projekt-Budget-Übersicht'!$A:$A,0)),""),IF($B$2="SV",IFERROR(INDEX('Projekt-Budget-Übersicht'!$H:$H,MATCH(A18,'Projekt-Budget-Übersicht'!$A:$A,0)),""),IF($B$2="CAD",IFERROR(INDEX('Projekt-Budget-Übersicht'!$I:$I,MATCH(A18,'Projekt-Budget-Übersicht'!$A:$A,0)),""),IF($B$2="ADM",IFERROR(INDEX('Projekt-Budget-Übersicht'!$J:$J,MATCH(A18,'Projekt-Budget-Übersicht'!$A:$A,0)),""),""))))) | M18: =IF($B$2="-","",L18*(F18+I18+K18)) | N18: =IFERROR(INDEX('Projekt-Budget-Übersicht'!$E:$E,MATCH(A18,'Projekt-Budget-Übersicht'!$A:$A,0)),"")
B19: SV | C19: G | D19: 12 | E19: 15.5 | F19: 0.5 | G19: 129.17 | I19: =IF(H19=0,"",F19-H19) | K19: 0 | L19: =IF($B$2="-","",IF($B$2="Pauschale",IFERROR(INDEX('Projekt-Budget-Übersicht'!$H:$H,MATCH(A19,'Projekt-Budget-Übersicht'!$A:$A,0)),""),IF($B$2="SV",IFERROR(INDEX('Projekt-Budget-Übersicht'!$H:$H,MATCH(A19,'Projekt-Budget-Übersicht'!$A:$A,0)),""),IF($B$2="CAD",IFERROR(INDEX('Projekt-Budget-Übersicht'!$I:$I,MATCH(A19,'Projekt-Budget-Übersicht'!$A:$A,0)),""),IF($B$2="ADM",IFERROR(INDEX('Projekt-Budget-Übersicht'!$J:$J,MATCH(A19,'Projekt-Budget-Übersicht'!$A:$A,0)),""),""))))) | M19: =IF($B$2="-","",L19*(F19+I19+K19)) | N19: =IFERROR(INDEX('Projekt-Budget-Übersicht'!$E:$E,MATCH(A19,'Projekt-Budget-Übersicht'!$A:$A,0)),"")
A20: 7247.01 Hoepfner-BST-Zentrale-Karlsruhe | B20: 0100-Anlage Projekt, Angebot, Versand, Auftrag | C20: G | D20: 1 | E20: 2 | F20: 1 | G20: 200 | I20: =IF(H20=0,"",F20-H20) | K20: 0 | L20: =IF($B$2="-","",IF($B$2="Pauschale",IFERROR(INDEX('Projekt-Budget-Übersicht'!$H:$H,MATCH(A20,'Projekt-Budget-Übersicht'!$A:$A,0)),""),IF($B$2="SV",IFERROR(INDEX('Projekt-Budget-Übersicht'!$H:$H,MATCH(A20,'Projekt-Budget-Übersicht'!$A:$A,0)),""),IF($B$2="CAD",IFERROR(INDEX('Projekt-Budget-Übersicht'!$I:$I,MATCH(A20,'Projekt-Budget-Übersicht'!$A:$A,0)),""),IF($B$2="ADM",IFERROR(INDEX('Projekt-Budget-Übersicht'!$J:$J,MATCH(A20,'Projekt-Budget-Übersicht'!$A:$A,0)),""),""))))) | M20: =IF($B$2="-","",L20*(F20+I20+K20)) | N20: =IFERROR(INDEX('Projekt-Budget-Übersicht'!$E:$E,MATCH(A20,'Projekt-Budget-Übersicht'!$A:$A,0)),"")
A21: 7293 VEW-BSK-WEA-Hopperkopf | B21: ADM | C21: G | D21: 1 | E21: 1.75 | F21: 0.5 | G21: 175 | I21: =IF(H21=0,"",F21-H21) | K21: 0 | L21: =IF($B$2="-","",IF($B$2="Pauschale",IFERROR(INDEX('Projekt-Budget-Übersicht'!$H:$H,MATCH(A21,'Projekt-Budget-Übersicht'!$A:$A,0)),""),IF($B$2="SV",IFERROR(INDEX('Projekt-Budget-Übersicht'!$H:$H,MATCH(A21,'Projekt-Budget-Übersicht'!$A:$A,0)),""),IF($B$2="CAD",IFERROR(INDEX('Projekt-Budget-Übersicht'!$I:$I,MATCH(A21,'Projekt-Budget-Übersicht'!$A:$A,0)),""),IF($B$2="ADM",IFERROR(INDEX('Projekt-Budget-Übersicht'!$J:$J,MATCH(A21,'Projekt-Budget-Übersicht'!$A:$A,0)),""),""))))) | M21: =IF($B$2="-","",L21*(F21+I21+K21)) | N21: =IFERROR(INDEX('Projekt-Budget-Übersicht'!$E:$E,MATCH(A21,'Projekt-Budget-Übersicht'!$A:$A,0)),"")
A22: 7422 Energieprojekte-DK-BSK-WEA-Aschbach-Ilmenau | B22: ADM | C22: G | D22: 1 | E22: 1.25 | F22: 0.5 | G22: 125 | I22: =IF(H22=0,"",F22-H22) | K22: 0 | L22: =IF($B$2="-","",IF($B$2="Pauschale",IFERROR(INDEX('Projekt-Budget-Übersicht'!$H:$H,MATCH(A22,'Projekt-Budget-Übersicht'!$A:$A,0)),""),IF($B$2="SV",IFERROR(INDEX('Projekt-Budget-Übersicht'!$H:$H,MATCH(A22,'Projekt-Budget-Übersicht'!$A:$A,0)),""),IF($B$2="CAD",IFERROR(INDEX('Projekt-Budget-Übersicht'!$I:$I,MATCH(A22,'Projekt-Budget-Übersicht'!$A:$A,0)),""),IF($B$2="ADM",IFERROR(INDEX('Projekt-Budget-Übersicht'!$J:$J,MATCH(A22,'Projekt-Budget-Übersicht'!$A:$A,0)),""),""))))) | M22: =IF($B$2="-","",L22*(F22+I22+K22)) | N22: =IFERROR(INDEX('Projekt-Budget-Übersicht'!$E:$E,MATCH(A22,'Projekt-Budget-Übersicht'!$A:$A,0)),"")
A23: 7435 wiwi-BSK-WEA-Spiesheim-Wörrstadt-Ost | B23: ADM | C23: G | D23: 1 | E23: 2 | F23: 0.5 | G23: 200 | I23: =IF(H23=0,"",F23-H23) | K23: 0 | L23: =IF($B$2="-","",IF($B$2="Pauschale",IFERROR(INDEX('Projekt-Budget-Übersicht'!$H:$H,MATCH(A23,'Projekt-Budget-Übersicht'!$A:$A,0)),""),IF($B$2="SV",IFERROR(INDEX('Projekt-Budget-Übersicht'!$H:$H,MATCH(A23,'Projekt-Budget-Übersicht'!$A:$A,0)),""),IF($B$2="CAD",IFERROR(INDEX('Projekt-Budget-Übersicht'!$I:$I,MATCH(A23,'Projekt-Budget-Übersicht'!$A:$A,0)),""),IF($B$2="ADM",IFERROR(INDEX('Projekt-Budget-Übersicht'!$J:$J,MATCH(A23,'Projekt-Budget-Übersicht'!$A:$A,0)),""),""))))) | M23: =IF($B$2="-","",L23*(F23+I23+K23)) | N23: =IFERROR(INDEX('Projekt-Budget-Übersicht'!$E:$E,MATCH(A23,'Projekt-Budget-Übersicht'!$A:$A,0)),"")
A24: 7437 MVV-BSK-UW3-Käfertal-Mannheim | B24: Anlage Projekt, Angebot, Versand, Auftrag | C24: G | D24: 1 | E24: 2 | F24: 0.5 | G24: 200 | I24: =IF(H24=0,"",F24-H24) | K24: 0 | L24: =IF($B$2="-","",IF($B$2="Pauschale",IFERROR(INDEX('Projekt-Budget-Übersicht'!$H:$H,MATCH(A24,'Projekt-Budget-Übersicht'!$A:$A,0)),""),IF($B$2="SV",IFERROR(INDEX('Projekt-Budget-Übersicht'!$H:$H,MATCH(A24,'Projekt-Budget-Übersicht'!$A:$A,0)),""),IF($B$2="CAD",IFERROR(INDEX('Projekt-Budget-Übersicht'!$I:$I,MATCH(A24,'Projekt-Budget-Übersicht'!$A:$A,0)),""),IF($B$2="ADM",IFERROR(INDEX('Projekt-Budget-Übersicht'!$J:$J,MATCH(A24,'Projekt-Budget-Übersicht'!$A:$A,0)),""),""))))) | M24: =IF($B$2="-","",L24*(F24+I24+K24)) | N24: =IFERROR(INDEX('Projekt-Budget-Übersicht'!$E:$E,MATCH(A24,'Projekt-Budget-Übersicht'!$A:$A,0)),"")
A25: 7441 Baupionier-Garagenpark-Öhringen-BSK | B25: ADM | C25: G | D25: 1 | E25: 2.25 | F25: 1 | G25: 225 | I25: =IF(H25=0,"",F25-H25) | K25: 0 | L25: =IF($B$2="-","",IF($B$2="Pauschale",IFERROR(INDEX('Projekt-Budget-Übersicht'!$H:$H,MATCH(A25,'Projekt-Budget-Übersicht'!$A:$A,0)),""),IF($B$2="SV",IFERROR(INDEX('Projekt-Budget-Übersicht'!$H:$H,MATCH(A25,'Projekt-Budget-Übersicht'!$A:$A,0)),""),IF($B$2="CAD",IFERROR(INDEX('Projekt-Budget-Übersicht'!$I:$I,MATCH(A25,'Projekt-Budget-Übersicht'!$A:$A,0)),""),IF($B$2="ADM",IFERROR(INDEX('Projekt-Budget-Übersicht'!$J:$J,MATCH(A25,'Projekt-Budget-Übersicht'!$A:$A,0)),""),""))))) | M25: =IF($B$2="-","",L25*(F25+I25+K25)) | N25: =IFERROR(INDEX('Projekt-Budget-Übersicht'!$E:$E,MATCH(A25,'Projekt-Budget-Übersicht'!$A:$A,0)),"")
A26: 7444 Energieprojekte-DK-BSK-WEA-Schußbachwald | B26: ADM | C26: G | D26: 1 | E26: 1.25 | F26: 0.5 | G26: 125 | I26: =IF(H26=0,"",F26-H26) | K26: 0 | L26: =IF($B$2="-","",IF($B$2="Pauschale",IFERROR(INDEX('Projekt-Budget-Übersicht'!$H:$H,MATCH(A26,'Projekt-Budget-Übersicht'!$A:$A,0)),""),IF($B$2="SV",IFERROR(INDEX('Projekt-Budget-Übersicht'!$H:$H,MATCH(A26,'Projekt-Budget-Übersicht'!$A:$A,0)),""),IF($B$2="CAD",IFERROR(INDEX('Projekt-Budget-Übersicht'!$I:$I,MATCH(A26,'Projekt-Budget-Übersicht'!$A:$A,0)),""),IF($B$2="ADM",IFERROR(INDEX('Projekt-Budget-Übersicht'!$J:$J,MATCH(A26,'Projekt-Budget-Übersicht'!$A:$A,0)),""),""))))) | M26: =IF($B$2="-","",L26*(F26+I26+K26)) | N26: =IFERROR(INDEX('Projekt-Budget-Übersicht'!$E:$E,MATCH(A26,'Projekt-Budget-Übersicht'!$A:$A,0)),"")
A27: 7445 Energieprojekte-DK-BSK-WEA-Thüngersheim | B27: ADM | C27: G | D27: 1 | E27: 1.25 | F27: 0.5 | G27: 125 | I27: =IF(H27=0,"",F27-H27) | K27: 0 | L27: =IF($B$2="-","",IF($B$2="Pauschale",IFERROR(INDEX('Projekt-Budget-Übersicht'!$H:$H,MATCH(A27,'Projekt-Budget-Übersicht'!$A:$A,0)),""),IF($B$2="SV",IFERROR(INDEX('Projekt-Budget-Übersicht'!$H:$H,MATCH(A27,'Projekt-Budget-Übersicht'!$A:$A,0)),""),IF($B$2="CAD",IFERROR(INDEX('Projekt-Budget-Übersicht'!$I:$I,MATCH(A27,'Projekt-Budget-Übersicht'!$A:$A,0)),""),IF($B$2="ADM",IFERROR(INDEX('Projekt-Budget-Übersicht'!$J:$J,MATCH(A27,'Projekt-Budget-Übersicht'!$A:$A,0)),""),""))))) | M27: =IF($B$2="-","",L27*(F27+I27+K27)) | N27: =IFERROR(INDEX('Projekt-Budget-Übersicht'!$E:$E,MATCH(A27,'Projekt-Budget-Übersicht'!$A:$A,0)),"")
A28: 7448 Seniorenresidenz-Sonnenwinkel-BSH-Im-Füllengarten14-16-Saarbrücken | B28: ADM | C28: G | D28: 5 | E28: 1.25 | F28: 0.5 | G28: 25 | I28: =IF(H28=0,"",F28-H28) | K28: 0 | L28: =IF($B$2="-","",IF($B$2="Pauschale",IFERROR(INDEX('Projekt-Budget-Übersicht'!$H:$H,MATCH(A28,'Projekt-Budget-Übersicht'!$A:$A,0)),""),IF($B$2="SV",IFERROR(INDEX('Projekt-Budget-Übersicht'!$H:$H,MATCH(A28,'Projekt-Budget-Übersicht'!$A:$A,0)),""),IF($B$2="CAD",IFERROR(INDEX('Projekt-Budget-Übersicht'!$I:$I,MATCH(A28,'Projekt-Budget-Übersicht'!$A:$A,0)),""),IF($B$2="ADM",IFERROR(INDEX('Projekt-Budget-Übersicht'!$J:$J,MATCH(A28,'Projekt-Budget-Übersicht'!$A:$A,0)),""),""))))) | M28: =IF($B$2="-","",L28*(F28+I28+K28)) | N28: =IFERROR(INDEX('Projekt-Budget-Übersicht'!$E:$E,MATCH(A28,'Projekt-Budget-Übersicht'!$A:$A,0)),"")
A29: 7459 Baupionier-BTB-Prüfung-Details-Garagenparks | B29: 0100-Anlage Projekt, Angebot, Versand, Auftrag | C29: G | D29: 1 | E29: 1.25 | F29: 0.5 | G29: 125 | I29: =IF(H29=0,"",F29-H29) | K29: 0 | L29: =IF($B$2="-","",IF($B$2="Pauschale",IFERROR(INDEX('Projekt-Budget-Übersicht'!$H:$H,MATCH(A29,'Projekt-Budget-Übersicht'!$A:$A,0)),""),IF($B$2="SV",IFERROR(INDEX('Projekt-Budget-Übersicht'!$H:$H,MATCH(A29,'Projekt-Budget-Übersicht'!$A:$A,0)),""),IF($B$2="CAD",IFERROR(INDEX('Projekt-Budget-Übersicht'!$I:$I,MATCH(A29,'Projekt-Budget-Übersicht'!$A:$A,0)),""),IF($B$2="ADM",IFERROR(INDEX('Projekt-Budget-Übersicht'!$J:$J,MATCH(A29,'Projekt-Budget-Übersicht'!$A:$A,0)),""),""))))) | M29: =IF($B$2="-","",L29*(F29+I29+K29)) | N29: =IFERROR(INDEX('Projekt-Budget-Übersicht'!$E:$E,MATCH(A29,'Projekt-Budget-Übersicht'!$A:$A,0)),"")
B30: 3100-Erarbeiten des Brandschutzkonzept/Nachweis/Stellungnahme | C30: G | D30: 14 | E30: 15.5 | F30: 0.5 | G30: 110.71 | I30: =IF(H30=0,"",F30-H30) | K30: =IF('E. Bieler'!J38="A. Kokott",'E. Bieler'!I38,0)+IF('M. Bandlofsky'!J17="A. Kokott",'M. Bandlofsky'!I17,0) | L30: =IF($B$2="-","",IF($B$2="Pauschale",IFERROR(INDEX('Projekt-Budget-Übersicht'!$H:$H,MATCH(A30,'Projekt-Budget-Übersicht'!$A:$A,0)),""),IF($B$2="SV",IFERROR(INDEX('Projekt-Budget-Übersicht'!$H:$H,MATCH(A30,'Projekt-Budget-Übersicht'!$A:$A,0)),""),IF($B$2="CAD",IFERROR(INDEX('Projekt-Budget-Übersicht'!$I:$I,MATCH(A30,'Projekt-Budget-Übersicht'!$A:$A,0)),""),IF($B$2="ADM",IFERROR(INDEX('Projekt-Budget-Übersicht'!$J:$J,MATCH(A30,'Projekt-Budget-Übersicht'!$A:$A,0)),""),""))))) | M30: =IF($B$2="-","",L30*(F30+I30+K30)) | N30: =IFERROR(INDEX('Projekt-Budget-Übersicht'!$E:$E,MATCH(A30,'Projekt-Budget-Übersicht'!$A:$A,0)),"")
B31: Summe | F31: 77.5
B32: Bonusberechtigte Stunden | F32: =G32+H32 | G32: 52 | H32: =SUM(H8,H9,H10,H11,H12,H13,H14,H15,H16,H17,H18,H19,H20,H21,H22,H23,H24,H25,H26,H27,H28,H29,H30)
B33: Bonusberechtigte Stunden Sonderprojekt | F33: =G33+H33 | G33: 16 | H33: =SUM(H6,H7)
B34: Zugeordnete Stunden von anderen MA | F34: =SUM(K6:K30)
B35: Gesamt Bonus Stunden | F35: =F32+F33+F34
A37: --- August 2025 ---
A38: Projekt | B38: Meilenstein | C38: Typ | D38: Soll (h) | E38: Ist (h) | F38: August 2025 (h) | G38: % | H38: Bonus-Anpassung (h) | I38: Differenz (h) | J38: Zuordnen an | K38: Von anderen (h) | L38: Stundensatz (€/h) | M38: Umsatz (€) | N38: Budget Gesamt (€) | O38: Budget Ist (€) | P38: Budget Erwirtschaftet (€)
A39: 0000 Sonderprojekt für Bonus | B39: Angebote-Ausschreibungen-Kalkulationen (max. 8h/Monat pro MA) | C39: M | D39: 8 | E39: 8 | F39: 8 | G39: 100 | I39: =IF(H39=0,"",F39-H39) | K39: =IF('J. Dorn'!J45="A. Kokott",'J. Dorn'!I45,0)+IF('O. Haag BS-CAD'!J51="A. Kokott",'O. Haag BS-CAD'!I51,0)+IF('P. Bergner'!J21="A. Kokott",'P. Bergner'!I21,0)+IF('R. Böttiger'!J31="A. Kokott",'R. Böttiger'!I31,0)+IF('T. Trautmann'!J28="A. Kokott",'T. Trautmann'!I28,0)+IF('U. Sutter ADM'!J28="A. Kokott",'U. Sutter ADM'!I28,0) | L39: =IF($B$2="-","",IF($B$2="Pauschale",IFERROR(INDEX('Projekt-Budget-Übersicht'!$H:$H,MATCH(A39,'Projekt-Budget-Übersicht'!$A:$A,0)),""),IF($B$2="SV",IFERROR(INDEX('Projekt-Budget-Übersicht'!$H:$H,MATCH(A39,'Projekt-Budget-Übersicht'!$A:$A,0)),""),IF($B$2="CAD",IFERROR(INDEX('Projekt-Budget-Übersicht'!$I:$I,MATCH(A39,'Projekt-Budget-Übersicht'!$A:$A,0)),""),IF($B$2="ADM",IFERROR(INDEX('Projekt-Budget-Übersicht'!$J:$J,MATCH(A39,'Projekt-Budget-Übersicht'!$A:$A,0)),""),""))))) | M39: =IF($B$2="-","",L39*(F39+I39+K39)) | N39: =IFERROR(INDEX('Projekt-Budget-Übersicht'!$E:$E,MATCH(A39,'Projekt-Budget-Übersicht'!$A:$A,0)),"")
B40: Einarbeitung neuer Mitarbeiter (max. 8h/Monat pro MA) | C40: M | D40: 8 | E40: 3 | F40: 3 | G40: 37.5 | I40: =IF(H40=0,"",F40-H40) | K40: =IF('M. Bandlofsky'!J26="A. Kokott",'M. Bandlofsky'!I26,0)+IF('O. Haag BS-CAD'!J52="A. Kokott",'O. Haag BS-CAD'!I52,0)+IF('P. Bergner'!J22="A. Kokott",'P. Bergner'!I22,0)+IF('R. Wagen CAD'!J31="A. Kokott",'R. Wagen CAD'!I31,0)+IF('T. Trautmann'!J29="A. Kokott",'T. Trautmann'!I29,0)+IF('U. Sutter ADM'!J29="A. Kokott",'U. Sutter ADM'!I29,0) | L40: =IF($B$2="-","",IF($B$2="Pauschale",IFERROR(INDEX('Projekt-Budget-Übersicht'!$H:$H,MATCH(A40,'Projekt-Budget-Übersicht'!$A:$A,0)),""),IF($B$2="SV",IFERROR(INDEX('Projekt-Budget-Übersicht'!$H:$H,MATCH(A40,'Projekt-Budget-Übersicht'!$A:$A,0)),""),IF($B$2="CAD",IFERROR(INDEX('Projekt-Budget-Übersicht'!$I:$I,MATCH(A40,'Projekt-Budget-Übersicht'!$A:$A,0)),""),IF($B$2="ADM",IFERROR(INDEX('Projekt-Budget-Übersicht'!$J:$J,MATCH(A40,'Projekt-Budget-Übersicht'!$A:$A,0)),""),""))))) | M40: =IF($B$2="-","",L40*(F40+I40+K40)) | N40: =IFERROR(INDEX('Projekt-Budget-Übersicht'!$E:$E,MATCH(A40,'Projekt-Budget-Übersicht'!$A:$A,0)),"")
A41: 2032.061 aam2core-FRP-Halbergstraße1-LU | B41: ADM | C41: G | D41: 1 | E41: 1.25 | F41: 0.5 | G41: 125 | I41: =IF(H41=0,"",F41-H41) | K41: 0 | L41: =IF($B$2="-","",IF($B$2="Pauschale",IFERROR(INDEX('Projekt-Budget-Übersicht'!$H:$H,MATCH(A41,'Projekt-Budget-Übersicht'!$A:$A,0)),""),IF($B$2="SV",IFERROR(INDEX('Projekt-Budget-Übersicht'!$H:$H,MATCH(A41,'Projekt-Budget-Übersicht'!$A:$A,0)),""),IF($B$2="CAD",IFERROR(INDEX('Projekt-Budget-Übersicht'!$I:$I,MATCH(A41,'Projekt-Budget-Übersicht'!$A:$A,0)),""),IF($B$2="ADM",IFERROR(INDEX('Projekt-Budget-Übersicht'!$J:$J,MATCH(A41,'Projekt-Budget-Übersicht'!$A:$A,0)),""),""))))) | M41: =IF($B$2="-","",L41*(F41+I41+K41)) | N41: =IFERROR(INDEX('Projekt-Budget-Übersicht'!$E:$E,MATCH(A41,'Projekt-Budget-Übersicht'!$A:$A,0)),"")
A42: 3258.30 Öztürk-FRP-DQ-Pilates-Studio-Marktstr1-3-Stuttgart | B42: ADM | C42: G | D42: 1 | E42: 1.25 | F42: 0.5 | G42: 125 | I42: =IF(H42=0,"",F42-H42) | K42: 0 | L42: =IF($B$2="-","",IF($B$2="Pauschale",IFERROR(INDEX('Projekt-Budget-Übersicht'!$H:$H,MATCH(A42,'Projekt-Budget-Übersicht'!$A:$A,0)),""),IF($B$2="SV",IFERROR(INDEX('Projekt-Budget-Übersicht'!$H:$H,MATCH(A42,'Projekt-Budget-Übersicht'!$A:$A,0)),""),IF($B$2="CAD",IFERROR(INDEX('Projekt-Budget-Übersicht'!$I:$I,MATCH(A42,'Projekt-Budget-Übersicht'!$A:$A,0)),""),IF($B$2="ADM",IFERROR(INDEX('Projekt-Budget-Übersicht'!$J:$J,MATCH(A42,'Projekt-Budget-Übersicht'!$A:$A,0)),""),""))))) | M42: =IF($B$2="-","",L42*(F42+I42+K42)) | N42: =IFERROR(INDEX('Projekt-Budget-Übersicht'!$E:$E,MATCH(A42,'Projekt-Budget-Übersicht'!$A:$A,0)),"")
...

Sheet C. Trapp SV
A1: C. Trapp SV - Quartalsreport 2025Q3
A2: Position: | B2: SV
A4: --- Juli 2025 ---
A5: Projekt | B5: Meilenstein | C5: Typ | D5: Soll (h) | E5: Ist (h) | F5: Juli 2025 (h) | G5: % | H5: Bonus-Anpassung (h) | I5: Differenz (h) | J5: Zuordnen an | K5: Von anderen (h) | L5: Stundensatz (€/h) | M5: Umsatz (€) | N5: Budget Gesamt (€) | O5: Budget Ist (€) | P5: Budget Erwirtschaftet (€)
A6: 0000 Sonderprojekt für Bonus | B6: Einarbeitung neuer Mitarbeiter (max. 8h/Monat pro MA) | C6: M | D6: 8 | E6: 1 | F6: 1 | G6: 12.5 | I6: =IF(H6=0,"",F6-H6) | K6: =IF('A. Kokott'!J7="C. Trapp SV",'A. Kokott'!I7,0)+IF('D. Brucker'!J7="C. Trapp SV",'D. Brucker'!I7,0)+IF('E. Bieler'!J7="C. Trapp SV",'E. Bieler'!I7,0)+IF('J. Dorchies'!J7="C. Trapp SV",'J. Dorchies'!I7,0)+IF('J. Dorn'!J6="C. Trapp SV",'J. Dorn'!I6,0)+IF('M. Bandlofsky'!J6="C. Trapp SV",'M. Bandlofsky'!I6,0)+IF('T. Trautmann'!J7="C. Trapp SV",'T. Trautmann'!I7,0)+IF('U. Sutter ADM'!J7="C. Trapp SV",'U. Sutter ADM'!I7,0) | L6: =IF($B$2="-","",IF($B$2="Pauschale",IFERROR(INDEX('Projekt-Budget-Übersicht'!$H:$H,MATCH(A6,'Projekt-Budget-Übersicht'!$A:$A,0)),""),IF($B$2="SV",IFERROR(INDEX('Projekt-Budget-Übersicht'!$H:$H,MATCH(A6,'Projekt-Budget-Übersicht'!$A:$A,0)),""),IF($B$2="CAD",IFERROR(INDEX('Projekt-Budget-Übersicht'!$I:$I,MATCH(A6,'Projekt-Budget-Übersicht'!$A:$A,0)),""),IF($B$2="ADM",IFERROR(INDEX('Projekt-Budget-Übersicht'!$J:$J,MATCH(A6,'Projekt-Budget-Übersicht'!$A:$A,0)),""),""))))) | M6: =IF($B$2="-","",L6*(F6+I6+K6)) | N6: =IFERROR(INDEX('Projekt-Budget-Übersicht'!$E:$E,MATCH(A6,'Projekt-Budget-Übersicht'!$A:$A,0)),"")
A7: 4126.041 Telluride-LP8-Bauzeitverlängerung-BA2-Klinikum-am-Gesundbrunnen-Heilbronn | B7: (aN) Pos. 2 weiterführende BAB über die Verlängerung der Bauzeit von 28 Monaten hinaus | C7: G | D7: 40 | E7: 468.75 | F7: 8 | G7: 1171.88 | I7: =IF(H7=0,"",F7-H7) | K7: =IF('U. Sutter ADM'!J9="C. Trapp SV",'U. Sutter ADM'!I9,0) | L7: =IF($B$2="-","",IF($B$2="Pauschale",IFERROR(INDEX('Projekt-Budget-Übersicht'!$H:$H,MATCH(A7,'Projekt-Budget-Übersicht'!$A:$A,0)),""),IF($B$2="SV",IFERROR(INDEX('Projekt-Budget-Übersicht'!$H:$H,MATCH(A7,'Projekt-Budget-Übersicht'!$A:$A,0)),""),IF($B$2="CAD",IFERROR(INDEX('Projekt-Budget-Übersicht'!$I:$I,MATCH(A7,'Projekt-Budget-Übersicht'!$A:$A,0)),""),IF($B$2="ADM",IFERROR(INDEX('Projekt-Budget-Übersicht'!$J:$J,MATCH(A7,'Projekt-Budget-Übersicht'!$A:$A,0)),""),""))))) | M7: =IF($B$2="-","",L7*(F7+I7+K7)) | N7: =IFERROR(INDEX('Projekt-Budget-Übersicht'!$E:$E,MATCH(A7,'Projekt-Budget-Übersicht'!$A:$A,0)),"")
A8: 4436.04 BTB Krankenhaus-Bergstraße-Viernheimer-Straße-2-Heppenheim | B8: 4105-Zusammenstellung Unterlagen für Einreichung bei BA…. | C8: G | D8: 6 | E8: 16.75 | F8: 4 | G8: 279.17 | I8: =IF(H8=0,"",F8-H8) | K8: =IF('U. Sutter ADM'!J10="C. Trapp SV",'U. Sutter ADM'!I10,0) | L8: =IF($B$2="-","",IF($B$2="Pauschale",IFERROR(INDEX('Projekt-Budget-Übersicht'!$H:$H,MATCH(A8,'Projekt-Budget-Übersicht'!$A:$A,0)),""),IF($B$2="SV",IFERROR(INDEX('Projekt-Budget-Übersicht'!$H:$H,MATCH(A8,'Projekt-Budget-Übersicht'!$A:$A,0)),""),IF($B$2="CAD",IFERROR(INDEX('Projekt-Budget-Übersicht'!$I:$I,MATCH(A8,'Projekt-Budget-Übersicht'!$A:$A,0)),""),IF($B$2="ADM",IFERROR(INDEX('Projekt-Budget-Übersicht'!$J:$J,MATCH(A8,'Projekt-Budget-Übersicht'!$A:$A,0)),""),""))))) | M8: =IF($B$2="-","",L8*(F8+I8+K8)) | N8: =IFERROR(INDEX('Projekt-Budget-Übersicht'!$E:$E,MATCH(A8,'Projekt-Budget-Übersicht'!$A:$A,0)),"")
B9: 5100-Beraten Planer ausführungsreife Lösungen…. | C9: G | D9: 52 | E9: 146.75 | F9: 8.75 | G9: 282.21 | I9: =IF(H9=0,"",F9-H9) | K9: =IF('S. Schüler'!J13="C. Trapp SV",'S. Schüler'!I13,0) | L9: =IF($B$2="-","",IF($B$2="Pauschale",IFERROR(INDEX('Projekt-Budget-Übersicht'!$H:$H,MATCH(A9,'Projekt-Budget-Übersicht'!$A:$A,0)),""),IF($B$2="SV",IFERROR(INDEX('Projekt-Budget-Übersicht'!$H:$H,MATCH(A9,'Projekt-Budget-Übersicht'!$A:$A,0)),""),IF($B$2="CAD",IFERROR(INDEX('Projekt-Budget-Übersicht'!$I:$I,MATCH(A9,'Projekt-Budget-Übersicht'!$A:$A,0)),""),IF($B$2="ADM",IFERROR(INDEX('Projekt-Budget-Übersicht'!$J:$J,MATCH(A9,'Projekt-Budget-Übersicht'!$A:$A,0)),""),""))))) | M9: =IF($B$2="-","",L9*(F9+I9+K9)) | N9: =IFERROR(INDEX('Projekt-Budget-Übersicht'!$E:$E,MATCH(A9,'Projekt-Budget-Übersicht'!$A:$A,0)),"")
B10: 5101-Mitwirken Koordination Fachplanung…. | C10: G | D10: 21 | E10: 30.25 | F10: 1.5 | G10: 144.05 | I10: =IF(H10=0,"",F10-H10) | K10: 0 | L10: =IF($B$2="-","",IF($B$2="Pauschale",IFERROR(INDEX('Projekt-Budget-Übersicht'!$H:$H,MATCH(A10,'Projekt-Budget-Übersicht'!$A:$A,0)),""),IF($B$2="SV",IFERROR(INDEX('Projekt-Budget-Übersicht'!$H:$H,MATCH(A10,'Projekt-Budget-Übersicht'!$A:$A,0)),""),IF($B$2="CAD",IFERROR(INDEX('Projekt-Budget-Übersicht'!$I:$I,MATCH(A10,'Projekt-Budget-Übersicht'!$A:$A,0)),""),IF($B$2="ADM",IFERROR(INDEX('Projekt-Budget-Übersicht'!$J:$J,MATCH(A10,'Projekt-Budget-Übersicht'!$A:$A,0)),""),""))))) | M10: =IF($B$2="-","",L10*(F10+I10+K10)) | N10: =IFERROR(INDEX('Projekt-Budget-Übersicht'!$E:$E,MATCH(A10,'Projekt-Budget-Übersicht'!$A:$A,0)),"")
B11: 5106-Prüfen auf zusätzl. genehmigungspfl. Sachverhalte.... | C11: G | D11: 5 | E11: 23.5 | F11: 16.5 | G11: 470 | I11: =IF(H11=0,"",F11-H11) | K11: 0 | L11: =IF($B$2="-","",IF($B$2="Pauschale",IFERROR(INDEX('Projekt-Budget-Übersicht'!$H:$H,MATCH(A11,'Projekt-Budget-Übersicht'!$A:$A,0)),""),IF($B$2="SV",IFERROR(INDEX('Projekt-Budget-Übersicht'!$H:$H,MATCH(A11,'Projekt-Budget-Übersicht'!$A:$A,0)),""),IF($B$2="CAD",IFERROR(INDEX('Projekt-Budget-Übersicht'!$I:$I,MATCH(A11,'Projekt-Budget-Übersicht'!$A:$A,0)),""),IF($B$2="ADM",IFERROR(INDEX('Projekt-Budget-Übersicht'!$J:$J,MATCH(A11,'Projekt-Budget-Übersicht'!$A:$A,0)),""),""))))) | M11: =IF($B$2="-","",L11*(F11+I11+K11)) | N11: =IFERROR(INDEX('Projekt-Budget-Übersicht'!$E:$E,MATCH(A11,'Projekt-Budget-Übersicht'!$A:$A,0)),"")
B12: 5205-Mitwirken Erstellen Brandmelde- und Alarmierungskonzept.... | C12: G | D12: 19 | E12: 1.5 | F12: 1.5 | G12: 7.89 | I12: =IF(H12=0,"",F12-H12) | K12: 0 | L12: =IF($B$2="-","",IF($B$2="Pauschale",IFERROR(INDEX('Projekt-Budget-Übersicht'!$H:$H,MATCH(A12,'Projekt-Budget-Übersicht'!$A:$A,0)),""),IF($B$2="SV",IFERROR(INDEX('Projekt-Budget-Übersicht'!$H:$H,MATCH(A12,'Projekt-Budget-Übersicht'!$A:$A,0)),""),IF($B$2="CAD",IFERROR(INDEX('Projekt-Budget-Übersicht'!$I:$I,MATCH(A12,'Projekt-Budget-Übersicht'!$A:$A,0)),""),IF($B$2="ADM",IFERROR(INDEX('Projekt-Budget-Übersicht'!$J:$J,MATCH(A12,'Projekt-Budget-Übersicht'!$A:$A,0)),""),""))))) | M12: =IF($B$2="-","",L12*(F12+I12+K12)) | N12: =IFERROR(INDEX('Projekt-Budget-Übersicht'!$E:$E,MATCH(A12,'Projekt-Budget-Übersicht'!$A:$A,0)),"")
A13: 5328 Flugfeldklinikum-Böblingen | B13: 5101-Mitwirken Koordination Fachplanung…. | C13: G | D13: 16 | E13: 68.75 | F13: 2.25 | G13: 429.69 | I13: =IF(H13=0,"",F13-H13) | K13: =IF('M. Bandlofsky'!J11="C. Trapp SV",'M. Bandlofsky'!I11,0) | L13: =IF($B$2="-","",IF($B$2="Pauschale",IFERROR(INDEX('Projekt-Budget-Übersicht'!$H:$H,MATCH(A13,'Projekt-Budget-Übersicht'!$A:$A,0)),""),IF($B$2="SV",IFERROR(INDEX('Projekt-Budget-Übersicht'!$H:$H,MATCH(A13,'Projekt-Budget-Übersicht'!$A:$A,0)),""),IF($B$2="CAD",IFERROR(INDEX('Projekt-Budget-Übersicht'!$I:$I,MATCH(A13,'Projekt-Budget-Übersicht'!$A:$A,0)),""),IF($B$2="ADM",IFERROR(INDEX('Projekt-Budget-Übersicht'!$J:$J,MATCH(A13,'Projekt-Budget-Übersicht'!$A:$A,0)),""),""))))) | M13: =IF($B$2="-","",L13*(F13+I13+K13)) | N13: =IFERROR(INDEX('Projekt-Budget-Übersicht'!$E:$E,MATCH(A13,'Projekt-Budget-Übersicht'!$A:$A,0)),"")
B14: 8100-Prüfen der Ausführung auf prinzipielle Übereinstimmung (Stufe 1).... | C14: G | D14: 610 | E14: 45.25 | F14: 32.75 | G14: 7.42 | I14: =IF(H14=0,"",F14-H14) | K14: 0 | L14: =IF($B$2="-","",IF($B$2="Pauschale",IFERROR(INDEX('Projekt-Budget-Übersicht'!$H:$H,MATCH(A14,'Projekt-Budget-Übersicht'!$A:$A,0)),""),IF($B$2="SV",IFERROR(INDEX('Projekt-Budget-Übersicht'!$H:$H,MATCH(A14,'Projekt-Budget-Übersicht'!$A:$A,0)),""),IF($B$2="CAD",IFERROR(INDEX('Projekt-Budget-Übersicht'!$I:$I,MATCH(A14,'Projekt-Budget-Übersicht'!$A:$A,0)),""),IF($B$2="ADM",IFERROR(INDEX('Projekt-Budget-Übersicht'!$J:$J,MATCH(A14,'Projekt-Budget-Übersicht'!$A:$A,0)),""),""))))) | M14: =IF($B$2="-","",L14*(F14+I14+K14)) | N14: =IFERROR(INDEX('Projekt-Budget-Übersicht'!$E:$E,MATCH(A14,'Projekt-Budget-Übersicht'!$A:$A,0)),"")
B15: 8101-Kontrolle Verwendbarkeitsnachweise/Bescheinigungen…. | C15: G | D15: 160 | E15: 22 | F15: 2 | G15: 13.75 | I15: =IF(H15=0,"",F15-H15) | K15: 0 | L15: =IF($B$2="-","",IF($B$2="Pauschale",IFERROR(INDEX('Projekt-Budget-Übersicht'!$H:$H,MATCH(A15,'Projekt-Budget-Übersicht'!$A:$A,0)),""),IF($B$2="SV",IFERROR(INDEX('Projekt-Budget-Übersicht'!$H:$H,MATCH(A15,'Projekt-Budget-Übersicht'!$A:$A,0)),""),IF($B$2="CAD",IFERROR(INDEX('Projekt-Budget-Übersicht'!$I:$I,MATCH(A15,'Projekt-Budget-Übersicht'!$A:$A,0)),""),IF($B$2="ADM",IFERROR(INDEX('Projekt-Budget-Übersicht'!$J:$J,MATCH(A15,'Projekt-Budget-Übersicht'!$A:$A,0)),""),""))))) | M15: =IF($B$2="-","",L15*(F15+I15+K15)) | N15: =IFERROR(INDEX('Projekt-Budget-Übersicht'!$E:$E,MATCH(A15,'Projekt-Budget-Übersicht'!$A:$A,0)),"")
B16: 8200-Prüfen der Ausführung - system. stichprobenart. Kontrolle (Stufe 2)…. | C16: G | D16: 562 | E16: 199 | F16: 31 | G16: 35.41 | I16: =IF(H16=0,"",F16-H16) | K16: 0 | L16: =IF($B$2="-","",IF($B$2="Pauschale",IFERROR(INDEX('Projekt-Budget-Übersicht'!$H:$H,MATCH(A16,'Projekt-Budget-Übersicht'!$A:$A,0)),""),IF($B$2="SV",IFERROR(INDEX('Projekt-Budget-Übersicht'!$H:$H,MATCH(A16,'Projekt-Budget-Übersicht'!$A:$A,0)),""),IF($B$2="CAD",IFERROR(INDEX('Projekt-Budget-Übersicht'!$I:$I,MATCH(A16,'Projekt-Budget-Übersicht'!$A:$A,0)),""),IF($B$2="ADM",IFERROR(INDEX('Projekt-Budget-Übersicht'!$J:$J,MATCH(A16,'Projekt-Budget-Übersicht'!$A:$A,0)),""),""))))) | M16: =IF($B$2="-","",L16*(F16+I16+K16)) | N16: =IFERROR(INDEX('Projekt-Budget-Übersicht'!$E:$E,MATCH(A16,'Projekt-Budget-Übersicht'!$A:$A,0)),"")
A17: 5607.05 BAB-NB-J4-Zentralinstitut-für-seelische-Gesundheit-Mannheim | B17: (aN) 8200-Prüfen der Ausführung - system. stichprobenart. Kontrolle (Stufe 2)…. | C17: G | D17: 240 | E17: 168.5 | F17: 18 | G17: 70.21 | I17: =IF(H17=0,"",F17-H17) | K17: =IF('U. Sutter ADM'!J15="C. Trapp SV",'U. Sutter ADM'!I15,0) | L17: =IF($B$2="-","",IF($B$2="Pauschale",IFERROR(INDEX('Projekt-Budget-Übersicht'!$H:$H,MATCH(A17,'Projekt-Budget-Übersicht'!$A:$A,0)),""),IF($B$2="SV",IFERROR(INDEX('Projekt-Budget-Übersicht'!$H:$H,MATCH(A17,'Projekt-Budget-Übersicht'!$A:$A,0)),""),IF($B$2="CAD",IFERROR(INDEX('Projekt-Budget-Übersicht'!$I:$I,MATCH(A17,'Projekt-Budget-Übersicht'!$A:$A,0)),""),IF($B$2="ADM",IFERROR(INDEX('Projekt-Budget-Übersicht'!$J:$J,MATCH(A17,'Projekt-Budget-Übersicht'!$A:$A,0)),""),""))))) | M17: =IF($B$2="-","",L17*(F17+I17+K17)) | N17: =IFERROR(INDEX('Projekt-Budget-Übersicht'!$E:$E,MATCH(A17,'Projekt-Budget-Übersicht'!$A:$A,0)),"")
B18: 5100-Beraten Planer ausführungsreife Lösungen…. | C18: G | D18: 25.25 | E18: 96 | F18: 1 | G18: 380.2 | I18: =IF(H18=0,"",F18-H18) | K18: 0 | L18: =IF($B$2="-","",IF($B$2="Pauschale",IFERROR(INDEX('Projekt-Budget-Übersicht'!$H:$H,MATCH(A18,'Projekt-Budget-Übersicht'!$A:$A,0)),""),IF($B$2="SV",IFERROR(INDEX('Projekt-Budget-Übersicht'!$H:$H,MATCH(A18,'Projekt-Budget-Übersicht'!$A:$A,0)),""),IF($B$2="CAD",IFERROR(INDEX('Projekt-Budget-Übersicht'!$I:$I,MATCH(A18,'Projekt-Budget-Übersicht'!$A:$A,0)),""),IF($B$2="ADM",IFERROR(INDEX('Projekt-Budget-Übersicht'!$J:$J,MATCH(A18,'Projekt-Budget-Übersicht'!$A:$A,0)),""),""))))) | M18: =IF($B$2="-","",L18*(F18+I18+K18)) | N18: =IFERROR(INDEX('Projekt-Budget-Übersicht'!$E:$E,MATCH(A18,'Projekt-Budget-Übersicht'!$A:$A,0)),"")
A19: 6564.01 ROB-MCR-Weilerbach-Züblin-TP1 | B19: 8000-Objektüberwachung | C19: G | D19: 3640 | E19: 175.5 | F19: 8.5 | G19: 4.82 | I19: =IF(H19=0,"",F19-H19) | K19: =IF('P. Bergner'!J8="C. Trapp SV",'P. Bergner'!I8,0) | L19: =IF($B$2="-","",IF($B$2="Pauschale",IFERROR(INDEX('Projekt-Budget-Übersicht'!$H:$H,MATCH(A19,'Projekt-Budget-Übersicht'!$A:$A,0)),""),IF($B$2="SV",IFERROR(INDEX('Projekt-Budget-Übersicht'!$H:$H,MATCH(A19,'Projekt-Budget-Übersicht'!$A:$A,0)),""),IF($B$2="CAD",IFERROR(INDEX('Projekt-Budget-Übersicht'!$I:$I,MATCH(A19,'Projekt-Budget-Übersicht'!$A:$A,0)),""),IF($B$2="ADM",IFERROR(INDEX('Projekt-Budget-Übersicht'!$J:$J,MATCH(A19,'Projekt-Budget-Übersicht'!$A:$A,0)),""),""))))) | M19: =IF($B$2="-","",L19*(F19+I19+K19)) | N19: =IFERROR(INDEX('Projekt-Budget-Übersicht'!$E:$E,MATCH(A19,'Projekt-Budget-Übersicht'!$A:$A,0)),"")
A20: 6643 BTB-FRP-FWP-Ersatzneubau-Krankenhaus-Hohenlohe-Öhringen-Vamed | B20: 5106-Prüfen auf zusätzl. genehmigungspfl. Sachverhalte.... | C20: G | D20: 16 | E20: 28.25 | F20: 3 | G20: 176.56 | I20: =IF(H20=0,"",F20-H20) | K20: 0 | L20: =IF($B$2="-","",IF($B$2="Pauschale",IFERROR(INDEX('Projekt-Budget-Übersicht'!$H:$H,MATCH(A20,'Projekt-Budget-Übersicht'!$A:$A,0)),""),IF($B$2="SV",IFERROR(INDEX('Projekt-Budget-Übersicht'!$H:$H,MATCH(A20,'Projekt-Budget-Übersicht'!$A:$A,0)),""),IF($B$2="CAD",IFERROR(INDEX('Projekt-Budget-Übersicht'!$I:$I,MATCH(A20,'Projekt-Budget-Übersicht'!$A:$A,0)),""),IF($B$2="ADM",IFERROR(INDEX('Projekt-Budget-Übersicht'!$J:$J,MATCH(A20,'Projekt-Budget-Übersicht'!$A:$A,0)),""),""))))) | M20: =IF($B$2="-","",L20*(F20+I20+K20)) | N20: =IFERROR(INDEX('Projekt-Budget-Übersicht'!$E:$E,MATCH(A20,'Projekt-Budget-Übersicht'!$A:$A,0)),"")
A21: 6704 BSK-BTB+FWP-FuR-ZsG-Lörrach | B21: 8101-Kontrolle Verwendbarkeitsnachweise/Bescheinigungen…. | C21: G | D21: 20 | E21: 33.75 | F21: 15.75 | G21: 168.75 | I21: =IF(H21=0,"",F21-H21) | K21: =IF('U. Sutter ADM'!J18="C. Trapp SV",'U. Sutter ADM'!I18,0) | L21: =IF($B$2="-","",IF($B$2="Pauschale",IFERROR(INDEX('Projekt-Budget-Übersicht'!$H:$H,MATCH(A21,'Projekt-Budget-Übersicht'!$A:$A,0)),""),IF($B$2="SV",IFERROR(INDEX('Projekt-Budget-Übersicht'!$H:$H,MATCH(A21,'Projekt-Budget-Übersicht'!$A:$A,0)),""),IF($B$2="CAD",IFERROR(INDEX('Projekt-Budget-Übersicht'!$I:$I,MATCH(A21,'Projekt-Budget-Übersicht'!$A:$A,0)),""),IF($B$2="ADM",IFERROR(INDEX('Projekt-Budget-Übersicht'!$J:$J,MATCH(A21,'Projekt-Budget-Übersicht'!$A:$A,0)),""),""))))) | M21: =IF($B$2="-","",L21*(F21+I21+K21)) | N21: =IFERROR(INDEX('Projekt-Budget-Übersicht'!$E:$E,MATCH(A21,'Projekt-Budget-Übersicht'!$A:$A,0)),"")
B22: 8104-Statusbericht Bewertung auf Möglichkeiten zur Inbetriebnahme…. | C22: G | D22: 40 | E22: 5 | F22: 2 | G22: 12.5 | I22: =IF(H22=0,"",F22-H22) | K22: 0 | L22: =IF($B$2="-","",IF($B$2="Pauschale",IFERROR(INDEX('Projekt-Budget-Übersicht'!$H:$H,MATCH(A22,'Projekt-Budget-Übersicht'!$A:$A,0)),""),IF($B$2="SV",IFERROR(INDEX('Projekt-Budget-Übersicht'!$H:$H,MATCH(A22,'Projekt-Budget-Übersicht'!$A:$A,0)),""),IF($B$2="CAD",IFERROR(INDEX('Projekt-Budget-Übersicht'!$I:$I,MATCH(A22,'Projekt-Budget-Übersicht'!$A:$A,0)),""),IF($B$2="ADM",IFERROR(INDEX('Projekt-Budget-Übersicht'!$J:$J,MATCH(A22,'Projekt-Budget-Übersicht'!$A:$A,0)),""),""))))) | M22: =IF($B$2="-","",L22*(F22+I22+K22)) | N22: =IFERROR(INDEX('Projekt-Budget-Übersicht'!$E:$E,MATCH(A22,'Projekt-Budget-Übersicht'!$A:$A,0)),"")
A23: 7313.01 BTS-Sachsenwaldhochhaus-Hamburger-Straße-49-Reinbek-OG-3-19+TK | B23: 1200-Bestandserfassung vor Ort.... | C23: G | D23: 18 | E23: 27 | F23: 20.5 | G23: 150 | I23: =IF(H23=0,"",F23-H23) | K23: 0 | L23: =IF($B$2="-","",IF($B$2="Pauschale",IFERROR(INDEX('Projekt-Budget-Übersicht'!$H:$H,MATCH(A23,'Projekt-Budget-Übersicht'!$A:$A,0)),""),IF($B$2="SV",IFERROR(INDEX('Projekt-Budget-Übersicht'!$H:$H,MATCH(A23,'Projekt-Budget-Übersicht'!$A:$A,0)),""),IF($B$2="CAD",IFERROR(INDEX('Projekt-Budget-Übersicht'!$I:$I,MATCH(A23,'Projekt-Budget-Übersicht'!$A:$A,0)),""),IF($B$2="ADM",IFERROR(INDEX('Projekt-Budget-Übersicht'!$J:$J,MATCH(A23,'Projekt-Budget-Übersicht'!$A:$A,0)),""),""))))) | M23: =IF($B$2="-","",L23*(F23+I23+K23)) | N23: =IFERROR(INDEX('Projekt-Budget-Übersicht'!$E:$E,MATCH(A23,'Projekt-Budget-Übersicht'!$A:$A,0)),"")
B24: Summe | F24: 178
B25: Bonusberechtigte Stunden | F25: =G25+H25 | G25: 95.75 | H25: =SUM(H7,H8,H9,H10,H11,H12,H13,H14,H15,H16,H17,H18,H19,H20,H21,H22,H23)
B26: Bonusberechtigte Stunden Sonderprojekt | F26: =G26+H26 | G26: 1 | H26: =SUM(H6)
B27: Zugeordnete Stunden von anderen MA | F27: =SUM(K6:K23)
B28: Gesamt Bonus Stunden | F28: =F25+F26+F27
A30: --- August 2025 ---
A31: Projekt | B31: Meilenstein | C31: Typ | D31: Soll (h) | E31: Ist (h) | F31: August 2025 (h) | G31: % | H31: Bonus-Anpassung (h) | I31: Differenz (h) | J31: Zuordnen an | K31: Von anderen (h) | L31: Stundensatz (€/h) | M31: Umsatz (€) | N31: Budget Gesamt (€) | O31: Budget Ist (€) | P31: Budget Erwirtschaftet (€)
A32: 0000 Sonderprojekt für Bonus | B32: Erstellung Vorlagen (übergreifend) (max. 8h/Monat pro MA) | C32: M | D32: 8 | E32: 3.5 | F32: 3.5 | G32: 43.75 | I32: =IF(H32=0,"",F32-H32) | K32: =IF('J. Dorn'!J46="C. Trapp SV",'J. Dorn'!I46,0)+IF('T. Trautmann'!J30="C. Trapp SV",'T. Trautmann'!I30,0) | L32: =IF($B$2="-","",IF($B$2="Pauschale",IFERROR(INDEX('Projekt-Budget-Übersicht'!$H:$H,MATCH(A32,'Projekt-Budget-Übersicht'!$A:$A,0)),""),IF($B$2="SV",IFERROR(INDEX('Projekt-Budget-Übersicht'!$H:$H,MATCH(A32,'Projekt-Budget-Übersicht'!$A:$A,0)),""),IF($B$2="CAD",IFERROR(INDEX('Projekt-Budget-Übersicht'!$I:$I,MATCH(A32,'Projekt-Budget-Übersicht'!$A:$A,0)),""),IF($B$2="ADM",IFERROR(INDEX('Projekt-Budget-Übersicht'!$J:$J,MATCH(A32,'Projekt-Budget-Übersicht'!$A:$A,0)),""),""))))) | M32: =IF($B$2="-","",L32*(F32+I32+K32)) | N32: =IFERROR(INDEX('Projekt-Budget-Übersicht'!$E:$E,MATCH(A32,'Projekt-Budget-Übersicht'!$A:$A,0)),"")
A33: 4126.041 Telluride-LP8-Bauzeitverlängerung-BA2-Klinikum-am-Gesundbrunnen-Heilbronn | B33: (aN) Pos. 2 weiterführende BAB über die Verlängerung der Bauzeit von 28 Monaten hinaus | C33: G | D33: 40 | E33: 472.75 | F33: 4 | G33: 1181.88 | I33: =IF(H33=0,"",F33-H33) | K33: 0 | L33: =IF($B$2="-","",IF($B$2="Pauschale",IFERROR(INDEX('Projekt-Budget-Übersicht'!$H:$H,MATCH(A33,'Projekt-Budget-Übersicht'!$A:$A,0)),""),IF($B$2="SV",IFERROR(INDEX('Projekt-Budget-Übersicht'!$H:$H,MATCH(A33,'Projekt-Budget-Übersicht'!$A:$A,0)),""),IF($B$2="CAD",IFERROR(INDEX('Projekt-Budget-Übersicht'!$I:$I,MATCH(A33,'Projekt-Budget-Übersicht'!$A:$A,0)),""),IF($B$2="ADM",IFERROR(INDEX('Projekt-Budget-Übersicht'!$J:$J,MATCH(A33,'Projekt-Budget-Übersicht'!$A:$A,0)),""),""))))) | M33: =IF($B$2="-","",L33*(F33+I33+K33)) | N33: =IFERROR(INDEX('Projekt-Budget-Übersicht'!$E:$E,MATCH(A33,'Projekt-Budget-Übersicht'!$A:$A,0)),"")
A34: 4436.04 BTB Krankenhaus-Bergstraße-Viernheimer-Straße-2-Heppenheim | B34: 5106-Prüfen auf zusätzl. genehmigungspfl. Sachverhalte.... | C34: G | D34: 5 | E34: 25 | F34: 1.5 | G34: 500 | I34: =IF(H34=0,"",F34-H34) | K34: 0 | L34: =IF($B$2="-","",IF($B$2="Pauschale",IFERROR(INDEX('Projekt-Budget-Übersicht'!$H:$H,MATCH(A34,'Projekt-Budget-Übersicht'!$A:$A,0)),""),IF($B$2="SV",IFERROR(INDEX('Projekt-Budget-Übersicht'!$H:$H,MATCH(A34,'Projekt-Budget-Übersicht'!$A:$A,0)),""),IF($B$2="CAD",IFERROR(INDEX('Projekt-Budget-Übersicht'!$I:$I,MATCH(A34,'Projekt-Budget-Übersicht'!$A:$A,0)),""),IF($B$2="ADM",IFERROR(INDEX('Projekt-Budget-Übersicht'!$J:$J,MATCH(A34,'Projekt-Budget-Übersicht'!$A:$A,0)),""),""))))) | M34: =IF($B$2="-","",L34*(F34+I34+K34)) | N34: =IFERROR(INDEX('Projekt-Budget-Übersicht'!$E:$E,MATCH(A34,'Projekt-Budget-Übersicht'!$A:$A,0)),"")
A35: 5328 Flugfeldklinikum-Böblingen | B35: 5100-Beraten Planer ausführungsreife Lösungen…. | C35: G | D35: 307.5 | E35: 390.25 | F35: 1.5 | G35: 126.91 | I35: =IF(H35=0,"",F35-H35) | K35: =IF('E. Bieler'!J50="C. Trapp SV",'E. Bieler'!I50,0)+IF('M. Bandlofsky'!J31="C. Trapp SV",'M. Bandlofsky'!I31,0) | L35: =IF($B$2="-","",IF($B$2="Pauschale",IFERROR(INDEX('Projekt-Budget-Übersicht'!$H:$H,MATCH(A35,'Projekt-Budget-Übersicht'!$A:$A,0)),""),IF($B$2="SV",IFERROR(INDEX('Projekt-Budget-Übersicht'!$H:$H,MATCH(A35,'Projekt-Budget-Übersicht'!$A:$A,0)),""),IF($B$2="CAD",IFERROR(INDEX('Projekt-Budget-Übersicht'!$I:$I,MATCH(A35,'Projekt-Budget-Übersicht'!$A:$A,0)),""),IF($B$2="ADM",IFERROR(INDEX('Projekt-Budget-Übersicht'!$J:$J,MATCH(A35,'Projekt-Budget-Übersicht'!$A:$A,0)),""),""))))) | M35: =IF($B$2="-","",L35*(F35+I35+K35)) | N35: =IFERROR(INDEX('Projekt-Budget-Übersicht'!$E:$E,MATCH(A35,'Projekt-Budget-Übersicht'!$A:$A,0)),"")
B36: 8100-Prüfen der Ausführung auf prinzipielle Übereinstimmung (Stufe 1).... | C36: G | D36: 610 | E36: 65.5 | F36: 14.5 | G36: 10.74 | I36: =IF(H36=0,"",F36-H36) | K36: =IF('E. Bieler'!J51="C. Trapp SV",'E. Bieler'!I51,0) | L36: =IF($B$2="-","",IF($B$2="Pauschale",IFERROR(INDEX('Projekt-Budget-Übersicht'!$H:$H,MATCH(A36,'Projekt-Budget-Übersicht'!$A:$A,0)),""),IF($B$2="SV",IFERROR(INDEX('Projekt-Budget-Übersicht'!$H:$H,MATCH(A36,'Projekt-Budget-Übersicht'!$A:$A,0)),""),IF($B$2="CAD",IFERROR(INDEX('Projekt-Budget-Übersicht'!$I:$I,MATCH(A36,'Projekt-Budget-Übersicht'!$A:$A,0)),""),IF($B$2="ADM",IFERROR(INDEX('Projekt-Budget-Übersicht'!$J:$J,MATCH(A36,'Projekt-Budget-Übersicht'!$A:$A,0)),""),""))))) | M36: =IF($B$2="-","",L36*(F36+I36+K36)) | N36: =IFERROR(INDEX('Projekt-Budget-Übersicht'!$E:$E,MATCH(A36,'Projekt-Budget-Übersicht'!$A:$A,0)),"")
